#VRML_SIM R2022b utf8

EXTERNPROTO "https://raw.githubusercontent.com/cyberbotics/webots/R2022b/projects/objects/backgrounds/protos/TexturedBackground.proto"
EXTERNPROTO "https://raw.githubusercontent.com/cyberbotics/webots/R2022b/projects/objects/backgrounds/protos/TexturedBackgroundLight.proto"
EXTERNPROTO "https://raw.githubusercontent.com/cyberbotics/webots/R2022b/projects/objects/floors/protos/CircleArena.proto"

WorldInfo {
}
Viewpoint {
  orientation -0.33185733874619844 -0.09874274160469809 0.9381474178937331 3.686018050088086
  position 1.700313773507203 1.0549607538959629 1.4846240848267684
  follow "custom_robot"
}
TexturedBackground {
}
TexturedBackgroundLight {
}
CircleArena {
}
Robot {
  children [
    HingeJoint {
      jointParameters HingeJointParameters {
        position 0
        axis 1 0 0
        anchor -0.055 -0.01 0
      }
      device [
        RotationalMotor {
          name "left wheel motor"
        }
      ]
      endPoint Solid {
        translation -0.055 -0.01 0
        children [
          DEF WHEEL Transform {
            rotation 1 0 0 1.5707996938995747
            children [
              Shape {
                appearance PBRAppearance {
                  baseColor 1 0 0
                  roughness 1
                  metalness 0
                }
                geometry Mesh {
                    url "meshes/wheel_link.dae"
                }
              }
            ]
          }
        ]
        name "left wheel"
        boundingObject Transform {
            rotation 0 1 0 1.5708
            translation 0.005 0 0
            children [
                Cylinder {
                    height 0.01
                    radius 0.027
                }
            ]
        }
        

        physics Physics {
        }
      }
    }
    HingeJoint {
      jointParameters HingeJointParameters {
        position 0
        axis 1 0 0
        anchor 0.045 -0.01 0
      }
      device [
        RotationalMotor {
          name "right wheel motor"
        }
      ]
      endPoint Solid {
        translation 0.045 -0.01 0
        children [
          USE WHEEL
        ]
        name "right wheel"
        boundingObject Transform {
            translation 0.005 0 0 
            rotation 0 1 0 1.5708
            children [
                Cylinder {
                    height 0.01
                    radius 0.027
                }
            ]
        }
        physics Physics {
        }
      }
    }
    HingeJoint {
      jointParameters HingeJointParameters {
          position 0 
          axis 0 1 0
          anchor 0 0.009 -0.05
      }
      endPoint Solid {
        translation 0 0.009 -0.05
        children [
          DEF AXLE Transform {
            rotation 1 0 0 1.5708
            children [
              Shape {
                appearance PBRAppearance {
                  baseColor 1 0 0
                  roughness 1
                  metalness 0
                }
                geometry Mesh {
                    url "meshes/axle_link.dae"
                }
              }
            ]
          }
        ]
        name "front axle"
        boundingObject Transform {
            rotation 1 0 0 1.5708
            children [
                Cylinder {
                    height 0.01
                    radius 0.0095
                }
            ]
        }
        physics Physics {
        }
      }
    }
    HingeJoint {
      jointParameters HingeJointParameters {
          position 0 
          axis 0 1 0
          anchor 0 0.009 0.05
      }
      endPoint Solid {
        translation 0 0.009 0.05
        children [
          DEF AXLE Transform {
            rotation 1 0 0 1.5708
            children [
              Shape {
                appearance PBRAppearance {
                  baseColor 1 0 0
                  roughness 1
                  metalness 0
                }
                geometry Mesh {
                    url "meshes/axle_link.dae"
                }
              }
            ]
          }
        ]
        name "back axle"
        boundingObject Transform {
            rotation 1 0 0 1.5708
            children [
                Cylinder {
                    height 0.01
                    radius 0.0095
                }
            ]
        }
        physics Physics {
        }
      }
    }
    Hinge2Joint {
        jointParameters HingeJointParameters {
            position 0
            anchor 0 0.009 0.05
            axis 0 1 0
        }
        jointParameters2 JointParameters {
            axis 1 0 0
        }
        endPoint Solid {
            translation 0 0.009 0.05
            children [
                DEF CASTER Transform {
                    rotation 1 0 0 1.5708
                    children [
                        Shape {
                            appearance PBRAppearance {
                                baseColor 1 0 0
                                roughness 1
                                metalness 0
                            }
                            geometry Mesh {
                                url "meshes/spinwheel_link.dae"
                            }
                        }
                    ]
                }
            ]
            name "back caster"
            boundingObject Transform {
                rotation 0 1 0 1.5708
                children [
                    Cylinder {
                        radius 0.0065
                        height 0.01385
                    }
                ]
            }
            physics Physics {

            }
        }
    }
    Hinge2Joint {
        jointParameters HingeJointParameters {
            position 0
            anchor 0 0.009 -0.05
            axis 0 1 0
        }
        jointParameters2 JointParameters {
            axis 1 0 0
        }
        endPoint Solid {
            translation 0 0.009 -0.05
            children [
                DEF CASTER Transform {
                    rotation 1 0 0 1.5708
                    children [
                        Shape {
                            appearance PBRAppearance {
                                baseColor 1 0 0
                                roughness 1
                                metalness 0
                            }
                            geometry Mesh {
                                url "meshes/spinwheel_link.dae"
                            }
                        }
                    ]
                }
            ]
            name "front caster"
            boundingObject Transform {
                rotation 0 1 0 1.5708
                children [
                    Cylinder {
                        radius 0.0065
                        height 0.01385
                    }
                ]
            }
            physics Physics {

            }
        }
    }
    Transform {
      children [
        Shape {
          appearance PBRAppearance {
            baseColor 0 0 1
            roughness 1
            metalness 0
          }
          geometry DEF BODY Mesh {
            url "meshes/base_link.dae"
          }
        }
      ]
    }
  ]
  boundingObject Transform {
    translation 0 -0.015 0
    rotation 1 0 0 1.5708
    children [
      Cylinder {
        height 0.060
        radius 0.075
      }
    ]
  }
  physics Physics {
  }
  controller "<extern>"
  name "custom_robot"
  rotation 1 0 0 -1.5708
}